Workbook

Sheet Instructions
A1: League Manager – Instructions | B1: Column Name | C1: Full Meaning | D1: Simple Explanation / How it’s Calculated
B2: P | C2: Played | D2: Total number of matches played
A3: 1) Setup (one-time) | B3: W | C3: Wins | D3: Number of matches won
A4: Players: enter all player names in Players!PlayerName (column B). | B4: D | C4: Draws | D4: Number of matches drawn
A5: Settings: set points for Win/Draw/Loss + Walkover points, and Walkover default score (3–0 by default). | B5: L | C5: Losses | D5: Number of matches lost
B6: GF | C6: Goals For | D6: Total goals scored
A7: 2) Entering match results | B7: GA | C7: Goals Against | D7: Total goals conceded
A8: Matches: fill ONLY Date, Home, Away, HomeGoals, AwayGoals, Status, Notes. | B8: GD | C8: Goal Difference | D8: GF − GA
A9: Status dropdown: | B9: PtsMatches | C9: Points from Matches | D9: Points earned from wins, draws, walkovers
A10: Played (normal result) | B10: PtsAdj | C10: Points Adjustment | D10: Manual admin adjustments (penalties/bonuses)
A11: Walkover_Home (Home awarded win; uses walkover default score + walkover points | B11: TotalPts | C11: Total Points | D11: PtsMatches + PtsAdj
A12: Walkover_Away (Away awarded win; uses walkover default score + walkover points) | B12: Pos | C12: Position | D12: Current leaderboard rank
A13: Cancelled (ignored completely) | B13: Clean Sheets | C13: Clean Sheets | D13: Matches where 0 goals were conceded
B14: Avg GF | C14: Average Goals For | D14: GF ÷ P
A15: 3) Deductions / penalties | B15: Avg GA | C15: Average Goals Against | D15: GA ÷ P
A16: Adjustments: add Player + PointsAdj (negative) + Reason. | B16: WinRate % | C16: Win Rate Percentage | D16: W ÷ P × 100
B17: Biggest Win | C17: Biggest Win Margin | D17: Largest goal difference in a win
A18: 4) Outputs | B18: Biggest Loss | C18: Biggest Loss Margin | D18: Largest goal difference in a loss
A19: Leaderboard: auto-sorted from Stats by TotalPts (tie-breakers: GD then GF then name). | B19: Walkovers Given | C19: Walkovers Given | D19: Times player forfeited (opponent got WO)
A20: Stats: full season metrics (clean sheets, averages, win rate, biggest win/loss, walkovers, etc.). | B20: Walkovers Received | C20: Walkovers Received | D20: Times player won by opponent forfeit
A21: Head2Head: pick two players and view their direct stats vs each other. | B21: Pts Per Game | C21: Points Per Game | D21: TotalPts ÷ P
A23: Google Sheets note:
A24: After you upload, confirm Data validation dropdowns still reference Players/Settings lists (Google sometimes resets them).

Sheet Settings
A1: CADE League Spreadsheet Settings
A3: Win Pts (Winner) | B3: 3
A4: Win Pts (Loser) | B4: 0
A5: Draw Pts (Each) | B5: 1
A6: Loss Pts (Loser) [optional] | B6: 0
A7: Walkover Pts (Winner) | B7: 3
A8: Walkover Pts (Loser) | B8: 0
A10: Walkover Winner Goals For | B10: 3
A11: Walkover Loser Goals For | B11: 0
A13: Status options (do not edit)
B14: Played
B15: Walkover_Home
B16: Walkover_Away
B17: Cancelled

Sheet Players
A1: Players (enter names once; used by dropdowns)
A2: PlayerID | B2: PlayerName
A3: 1 | B3: MR OGA
A4: 2 | B4: ANIFE
A5: 3 | B5: BAJI SNR
A6: 4 | B6: GURU
A7: 5 | B7: KAYKAY
A8: 6 | B8: TACTICAL
A9: 7 | B9: WOLEVATION
A10: 8 | B10: KHALEEDOY
A11: 9 | B11: BALO K
A12: 10 | B12: YEMOLEE
A13: 11 | B13: RHYMEZ
A14: 12 | B14: SIMPLYY UZO
... A22: 20 | B22: KINGNONEX

Sheet Matches
A1: Match Input (blue cells). Enter Date, Home, Away, Scores OR choose Walkover status.
A2: MatchID | B2: Date | C2: Home | D2: Away | E2: Home Goals (input) | F2: Away Goals (input) | G2: Status | H2: Home Goals (effective) | I2: Away Goals (effective) | J2: Home Pts | K2: Away Pts | L2: Played Flag | M2: Home W | N2: Home D | O2: Home L | P2: Away W | Q2: Away D | R2: Away L | S2: Winner | T2: Notes | U2: Home Margin | V2: Away Margin | W2: Home Loss Margin | X2: Away Loss Margin
A3: 1 | B3: 46039 | C3: ANIFE | D3: MR OGA | E3: 7 | F3: 7 | G3: Played | H3: =IF($G3="Walkover_Home",Settings!$B$10,IF($G3="Walkover_Away",Settings!$B$11,IF($G3="Cancelled","",IF($E3="","",$E3)))) -> 7 | I3: =IF($G3="Walkover_Home",Settings!$B$11,IF($G3="Walkover_Away",Settings!$B$10,IF($G3="Cancelled","",IF($F3="","",$F3)))) -> 7 | J3: =IF($L3=0,"",IF($G3="Walkover_Home",Settings!$B$7,IF($G3="Walkover_Away",Settings!$B$8,IF($H3>$I3,Settings!$B$3,IF($H3<$I3,Settings!$B$4,Settings!$B$5))))) -> 1 | K3: =IF($L3=0,"",IF($G3="Walkover_Home",Settings!$B$8,IF($G3="Walkover_Away",Settings!$B$7,IF($I3>$H3,Settings!$B$3,IF($I3<$H3,Settings!$B$4,Settings!$B$5))))) -> 1 | L3: =IF($G3="Cancelled",0,IF(OR($H3="", $I3=""),0,1)) -> 1 | M3: =IF($L3=0,"",IF($H3>$I3,1,0)) -> 0 | N3: =IF($L3=0,"",IF($H3=$I3,1,0)) -> 1 | O3: =IF($L3=0,"",IF($H3<$I3,1,0)) -> 0 | P3: =IF($L3=0,"",IF($I3>$H3,1,0)) -> 0 | Q3: =IF($L3=0,"",IF($I3=$H3,1,0)) -> 1 | R3: =IF($L3=0,"",IF($I3<$H3,1,0)) -> 0 | S3: =IF($L3=0,"",IF($H3>$I3,$C3,IF($H3<$I3,$D3,"Draw"))) -> Draw | U3: =IF($L3=0,"",$H3-$I3) -> 0 | V3: =IF($L3=0,"",$I3-$H3) -> 0 | W3: =IF($L3=0,"",$I3-$H3) -> 0 | X3: =IF($L3=0,"",$H3-$I3) -> 0
A4: 2 | B4: 46039 | C4: RHYMEZ | D4: SIMPLYY UZO | E4: 8 | F4: 2 | G4: Played | H4: =IF($G4="Walkover_Home",Settings!$B$10,IF($G4="Walkover_Away",Settings!$B$11,IF($G4="Cancelled","",IF($E4="","",$E4)))) -> 8 | I4: =IF($G4="Walkover_Home",Settings!$B$11,IF($G4="Walkover_Away",Settings!$B$10,IF($G4="Cancelled","",IF($F4="","",$F4)))) -> 2 | J4: =IF($L4=0,"",IF($G4="Walkover_Home",Settings!$B$7,IF($G4="Walkover_Away",Settings!$B$8,IF($H4>$I4,Settings!$B$3,IF($H4<$I4,Settings!$B$4,Settings!$B$5))))) -> 3 | K4: =IF($L4=0,"",IF($G4="Walkover_Home",Settings!$B$8,IF($G4="Walkover_Away",Settings!$B$7,IF($I4>$H4,Settings!$B$3,IF($I4<$H4,Settings!$B$4,Settings!$B$5))))) -> 0 | L4: =IF($G4="Cancelled",0,IF(OR($H4="", $I4=""),0,1)) -> 1 | M4: =IF($L4=0,"",IF($H4>$I4,1,0)) -> 1 | N4: =IF($L4=0,"",IF($H4=$I4,1,0)) -> 0 | O4: =IF($L4=0,"",IF($H4<$I4,1,0)) -> 0 | P4: =IF($L4=0,"",IF($I4>$H4,1,0)) -> 0 | Q4: =IF($L4=0,"",IF($I4=$H4,1,0)) -> 0 | R4: =IF($L4=0,"",IF($I4<$H4,1,0)) -> 1 | S4: =IF($L4=0,"",IF($H4>$I4,$C4,IF($H4<$I4,$D4,"Draw"))) -> RHYMEZ | U4: =IF($L4=0,"",$H4-$I4) -> 6 | V4: =IF($L4=0,"",$I4-$H4) -> -6 | W4: =IF($L4=0,"",$I4-$H4) -> -6 | X4: =IF($L4=0,"",$H4-$I4) -> 6
A5: 3 | B5: 46039 | C5: GURU | D5: BAJI SNR | E5: 3 | F5: 5 | G5: Played | H5: =IF($G5="Walkover_Home",Settings!$B$10,IF($G5="Walkover_Away",Settings!$B$11,IF($G5="Cancelled","",IF($E5="","",$E5)))) -> 3 | I5: =IF($G5="Walkover_Home",Settings!$B$11,IF($G5="Walkover_Away",Settings!$B$10,IF($G5="Cancelled","",IF($F5="","",$F5)))) -> 5 | J5: =IF($L5=0,"",IF($G5="Walkover_Home",Settings!$B$7,IF($G5="Walkover_Away",Settings!$B$8,IF($H5>$I5,Settings!$B$3,IF($H5<$I5,Settings!$B$4,Settings!$B$5))))) -> 0 | K5: =IF($L5=0,"",IF($G5="Walkover_Home",Settings!$B$8,IF($G5="Walkover_Away",Settings!$B$7,IF($I5>$H5,Settings!$B$3,IF($I5<$H5,Settings!$B$4,Settings!$B$5))))) -> 3 | L5: =IF($G5="Cancelled",0,IF(OR($H5="", $I5=""),0,1)) -> 1 | M5: =IF($L5=0,"",IF($H5>$I5,1,0)) -> 0 | N5: =IF($L5=0,"",IF($H5=$I5,1,0)) -> 0 | O5: =IF($L5=0,"",IF($H5<$I5,1,0)) -> 1 | P5: =IF($L5=0,"",IF($I5>$H5,1,0)) -> 1 | Q5: =IF($L5=0,"",IF($I5=$H5,1,0)) -> 0 | R5: =IF($L5=0,"",IF($I5<$H5,1,0)) -> 0 | S5: =IF($L5=0,"",IF($H5>$I5,$C5,IF($H5<$I5,$D5,"Draw"))) -> BAJI SNR | U5: =IF($L5=0,"",$H5-$I5) -> -2 | V5: =IF($L5=0,"",$I5-$H5) -> 2 | W5: =IF($L5=0,"",$I5-$H5) -> 2 | X5: =IF($L5=0,"",$H5-$I5) -> -2
A6: 4 | B6: 46039 | C6: GAMEWITHJOSH | D6: BLAISE99 | E6: 2 | F6: 10 | G6: Played | H6: =IF($G6="Walkover_Home",Settings!$B$10,IF($G6="Walkover_Away",Settings!$B$11,IF($G6="Cancelled","",IF($E6="","",$E6)))) -> 2 | I6: =IF($G6="Walkover_Home",Settings!$B$11,IF($G6="Walkover_Away",Settings!$B$10,IF($G6="Cancelled","",IF($F6="","",$F6)))) -> 10 | J6: =IF($L6=0,"",IF($G6="Walkover_Home",Settings!$B$7,IF($G6="Walkover_Away",Settings!$B$8,IF($H6>$I6,Settings!$B$3,IF($H6<$I6,Settings!$B$4,Settings!$B$5))))) -> 0 | K6: =IF($L6=0,"",IF($G6="Walkover_Home",Settings!$B$8,IF($G6="Walkover_Away",Settings!$B$7,IF($I6>$H6,Settings!$B$3,IF($I6<$H6,Settings!$B$4,Settings!$B$5))))) -> 3 | L6: =IF($G6="Cancelled",0,IF(OR($H6="", $I6=""),0,1)) -> 1 | M6: =IF($L6=0,"",IF($H6>$I6,1,0)) -> 0 | N6: =IF($L6=0,"",IF($H6=$I6,1,0)) -> 0 | O6: =IF($L6=0,"",IF($H6<$I6,1,0)) -> 1 | P6: =IF($L6=0,"",IF($I6>$H6,1,0)) -> 1 | Q6: =IF($L6=0,"",IF($I6=$H6,1,0)) -> 0 | R6: =IF($L6=0,"",IF($I6<$H6,1,0)) -> 0 | S6: =IF($L6=0,"",IF($H6>$I6,$C6,IF($H6<$I6,$D6,"Draw"))) -> BLAISE99 | U6: =IF($L6=0,"",$H6-$I6) -> -8 | V6: =IF($L6=0,"",$I6-$H6) -> 8 | W6: =IF($L6=0,"",$I6-$H6) -> 8 | X6: =IF($L6=0,"",$H6-$I6) -> -8
A7: 5 | B7: 46039 | C7: TACTICAL | D7: KAYKAY | E7: 3 | F7: 7 | G7: Played | H7: =IF($G7="Walkover_Home",Settings!$B$10,IF($G7="Walkover_Away",Settings!$B$11,IF($G7="Cancelled","",IF($E7="","",$E7)))) -> 3 | I7: =IF($G7="Walkover_Home",Settings!$B$11,IF($G7="Walkover_Away",Settings!$B$10,IF($G7="Cancelled","",IF($F7="","",$F7)))) -> 7 | J7: =IF($L7=0,"",IF($G7="Walkover_Home",Settings!$B$7,IF($G7="Walkover_Away",Settings!$B$8,IF($H7>$I7,Settings!$B$3,IF($H7<$I7,Settings!$B$4,Settings!$B$5))))) -> 0 | K7: =IF($L7=0,"",IF($G7="Walkover_Home",Settings!$B$8,IF($G7="Walkover_Away",Settings!$B$7,IF($I7>$H7,Settings!$B$3,IF($I7<$H7,Settings!$B$4,Settings!$B$5))))) -> 3 | L7: =IF($G7="Cancelled",0,IF(OR($H7="", $I7=""),0,1)) -> 1 | M7: =IF($L7=0,"",IF($H7>$I7,1,0)) -> 0 | N7: =IF($L7=0,"",IF($H7=$I7,1,0)) -> 0 | O7: =IF($L7=0,"",IF($H7<$I7,1,0)) -> 1 | P7: =IF($L7=0,"",IF($I7>$H7,1,0)) -> 1 | Q7: =IF($L7=0,"",IF($I7=$H7,1,0)) -> 0 | R7: =IF($L7=0,"",IF($I7<$H7,1,0)) -> 0 | S7: =IF($L7=0,"",IF($H7>$I7,$C7,IF($H7<$I7,$D7,"Draw"))) -> KAYKAY | U7: =IF($L7=0,"",$H7-$I7) -> -4 | V7: =IF($L7=0,"",$I7-$H7) -> 4 | W7: =IF($L7=0,"",$I7-$H7) -> 4 | X7: =IF($L7=0,"",$H7-$I7) -> -4
A8: 6 | B8: 46039 | C8: SON OF GOD | D8: DADABOI | E8: 7 | F8: 0 | G8: Played | H8: =IF($G8="Walkover_Home",Settings!$B$10,IF($G8="Walkover_Away",Settings!$B$11,IF($G8="Cancelled","",IF($E8="","",$E8)))) -> 7 | I8: =IF($G8="Walkover_Home",Settings!$B$11,IF($G8="Walkover_Away",Settings!$B$10,IF($G8="Cancelled","",IF($F8="","",$F8)))) -> 0 | J8: =IF($L8=0,"",IF($G8="Walkover_Home",Settings!$B$7,IF($G8="Walkover_Away",Settings!$B$8,IF($H8>$I8,Settings!$B$3,IF($H8<$I8,Settings!$B$4,Settings!$B$5))))) -> 3 | K8: =IF($L8=0,"",IF($G8="Walkover_Home",Settings!$B$8,IF($G8="Walkover_Away",Settings!$B$7,IF($I8>$H8,Settings!$B$3,IF($I8<$H8,Settings!$B$4,Settings!$B$5))))) -> 0 | L8: =IF($G8="Cancelled",0,IF(OR($H8="", $I8=""),0,1)) -> 1 | M8: =IF($L8=0,"",IF($H8>$I8,1,0)) -> 1 | N8: =IF($L8=0,"",IF($H8=$I8,1,0)) -> 0 | O8: =IF($L8=0,"",IF($H8<$I8,1,0)) -> 0 | P8: =IF($L8=0,"",IF($I8>$H8,1,0)) -> 0 | Q8: =IF($L8=0,"",IF($I8=$H8,1,0)) -> 0 | R8: =IF($L8=0,"",IF($I8<$H8,1,0)) -> 1 | S8: =IF($L8=0,"",IF($H8>$I8,$C8,IF($H8<$I8,$D8,"Draw"))) -> SON OF GOD | U8: =IF($L8=0,"",$H8-$I8) -> 7 | V8: =IF($L8=0,"",$I8-$H8) -> -7 | W8: =IF($L8=0,"",$I8-$H8) -> -7 | X8: =IF($L8=0,"",$H8-$I8) -> 7
A9: 7 | B9: 46039 | C9: KHALEEDOY | D9: WOLEVATION | G9: Walkover_Away | H9: =IF($G9="Walkover_Home",Settings!$B$10,IF($G9="Walkover_Away",Settings!$B$11,IF($G9="Cancelled","",IF($E9="","",$E9)))) -> 0 | I9: =IF($G9="Walkover_Home",Settings!$B$11,IF($G9="Walkover_Away",Settings!$B$10,IF($G9="Cancelled","",IF($F9="","",$F9)))) -> 3 | J9: =IF($L9=0,"",IF($G9="Walkover_Home",Settings!$B$7,IF($G9="Walkover_Away",Settings!$B$8,IF($H9>$I9,Settings!$B$3,IF($H9<$I9,Settings!$B$4,Settings!$B$5))))) -> 0 | K9: =IF($L9=0,"",IF($G9="Walkover_Home",Settings!$B$8,IF($G9="Walkover_Away",Settings!$B$7,IF($I9>$H9,Settings!$B$3,IF($I9<$H9,Settings!$B$4,Settings!$B$5))))) -> 3 | L9: =IF($G9="Cancelled",0,IF(OR($H9="", $I9=""),0,1)) -> 1 | M9: =IF($L9=0,"",IF($H9>$I9,1,0)) -> 0 | N9: =IF($L9=0,"",IF($H9=$I9,1,0)) -> 0 | O9: =IF($L9=0,"",IF($H9<$I9,1,0)) -> 1 | P9: =IF($L9=0,"",IF($I9>$H9,1,0)) -> 1 | Q9: =IF($L9=0,"",IF($I9=$H9,1,0)) -> 0 | R9: =IF($L9=0,"",IF($I9<$H9,1,0)) -> 0 | S9: =IF($L9=0,"",IF($H9>$I9,$C9,IF($H9<$I9,$D9,"Draw"))) -> WOLEVATION | U9: =IF($L9=0,"",$H9-$I9) -> -3 | V9: =IF($L9=0,"",$I9-$H9) -> 3 | W9: =IF($L9=0,"",$I9-$H9) -> 3 | X9: =IF($L9=0,"",$H9-$I9) -> -3
A10: 8 | B10: 46039 | C10: FLICK | D10: DRACARYS | E10: 5 | F10: 5 | G10: Played | H10: =IF($G10="Walkover_Home",Settings!$B$10,IF($G10="Walkover_Away",Settings!$B$11,IF($G10="Cancelled","",IF($E10="","",$E10)))) -> 5 | I10: =IF($G10="Walkover_Home",Settings!$B$11,IF($G10="Walkover_Away",Settings!$B$10,IF($G10="Cancelled","",IF($F10="","",$F10)))) -> 5 | J10: =IF($L10=0,"",IF($G10="Walkover_Home",Settings!$B$7,IF($G10="Walkover_Away",Settings!$B$8,IF($H10>$I10,Settings!$B$3,IF($H10<$I10,Settings!$B$4,Settings!$B$5))))) -> 1 | K10: =IF($L10=0,"",IF($G10="Walkover_Home",Settings!$B$8,IF($G10="Walkover_Away",Settings!$B$7,IF($I10>$H10,Settings!$B$3,IF($I10<$H10,Settings!$B$4,Settings!$B$5))))) -> 1 | L10: =IF($G10="Cancelled",0,IF(OR($H10="", $I10=""),0,1)) -> 1 | M10: =IF($L10=0,"",IF($H10>$I10,1,0)) -> 0 | N10: =IF($L10=0,"",IF($H10=$I10,1,0)) -> 1 | O10: =IF($L10=0,"",IF($H10<$I10,1,0)) -> 0 | P10: =IF($L10=0,"",IF($I10>$H10,1,0)) -> 0 | Q10: =IF($L10=0,"",IF($I10=$H10,1,0)) -> 1 | R10: =IF($L10=0,"",IF($I10<$H10,1,0)) -> 0 | S10: =IF($L10=0,"",IF($H10>$I10,$C10,IF($H10<$I10,$D10,"Draw"))) -> Draw | U10: =IF($L10=0,"",$H10-$I10) -> 0 | V10: =IF($L10=0,"",$I10-$H10) -> 0 | W10: =IF($L10=0,"",$I10-$H10) -> 0 | X10: =IF($L10=0,"",$H10-$I10) -> 0
A11: 9 | B11: 46039 | C11: KINGNONEX | D11: BRIGHT | E11: 5 | F11: 1 | G11: Played | H11: =IF($G11="Walkover_Home",Settings!$B$10,IF($G11="Walkover_Away",Settings!$B$11,IF($G11="Cancelled","",IF($E11="","",$E11)))) -> 5 | I11: =IF($G11="Walkover_Home",Settings!$B$11,IF($G11="Walkover_Away",Settings!$B$10,IF($G11="Cancelled","",IF($F11="","",$F11)))) -> 1 | J11: =IF($L11=0,"",IF($G11="Walkover_Home",Settings!$B$7,IF($G11="Walkover_Away",Settings!$B$8,IF($H11>$I11,Settings!$B$3,IF($H11<$I11,Settings!$B$4,Settings!$B$5))))) -> 3 | K11: =IF($L11=0,"",IF($G11="Walkover_Home",Settings!$B$8,IF($G11="Walkover_Away",Settings!$B$7,IF($I11>$H11,Settings!$B$3,IF($I11<$H11,Settings!$B$4,Settings!$B$5))))) -> 0 | L11: =IF($G11="Cancelled",0,IF(OR($H11="", $I11=""),0,1)) -> 1 | M11: =IF($L11=0,"",IF($H11>$I11,1,0)) -> 1 | N11: =IF($L11=0,"",IF($H11=$I11,1,0)) -> 0 | O11: =IF($L11=0,"",IF($H11<$I11,1,0)) -> 0 | P11: =IF($L11=0,"",IF($I11>$H11,1,0)) -> 0 | Q11: =IF($L11=0,"",IF($I11=$H11,1,0)) -> 0 | R11: =IF($L11=0,"",IF($I11<$H11,1,0)) -> 1 | S11: =IF($L11=0,"",IF($H11>$I11,$C11,IF($H11<$I11,$D11,"Draw"))) -> KINGNONEX | U11: =IF($L11=0,"",$H11-$I11) -> 4 | V11: =IF($L11=0,"",$I11-$H11) -> -4 | W11: =IF($L11=0,"",$I11-$H11) -> -4 | X11: =IF($L11=0,"",$H11-$I11) -> 4
A12: 10 | B12: 46039 | C12: BALO K | D12: YEMOLEE | E12: 3 | F12: 5 | G12: Played | H12: =IF($G12="Walkover_Home",Settings!$B$10,IF($G12="Walkover_Away",Settings!$B$11,IF($G12="Cancelled","",IF($E12="","",$E12)))) -> 3 | I12: =IF($G12="Walkover_Home",Settings!$B$11,IF($G12="Walkover_Away",Settings!$B$10,IF($G12="Cancelled","",IF($F12="","",$F12)))) -> 5 | J12: =IF($L12=0,"",IF($G12="Walkover_Home",Settings!$B$7,IF($G12="Walkover_Away",Settings!$B$8,IF($H12>$I12,Settings!$B$3,IF($H12<$I12,Settings!$B$4,Settings!$B$5))))) -> 0 | K12: =IF($L12=0,"",IF($G12="Walkover_Home",Settings!$B$8,IF($G12="Walkover_Away",Settings!$B$7,IF($I12>$H12,Settings!$B$3,IF($I12<$H12,Settings!$B$4,Settings!$B$5))))) -> 3 | L12: =IF($G12="Cancelled",0,IF(OR($H12="", $I12=""),0,1)) -> 1 | M12: =IF($L12=0,"",IF($H12>$I12,1,0)) -> 0 | N12: =IF($L12=0,"",IF($H12=$I12,1,0)) -> 0 | O12: =IF($L12=0,"",IF($H12<$I12,1,0)) -> 1 | P12: =IF($L12=0,"",IF($I12>$H12,1,0)) -> 1 | Q12: =IF($L12=0,"",IF($I12=$H12,1,0)) -> 0 | R12: =IF($L12=0,"",IF($I12<$H12,1,0)) -> 0 | S12: =IF($L12=0,"",IF($H12>$I12,$C12,IF($H12<$I12,$D12,"Draw"))) -> YEMOLEE | U12: =IF($L12=0,"",$H12-$I12) -> -2 | V12: =IF($L12=0,"",$I12-$H12) -> 2 | W12: =IF($L12=0,"",$I12-$H12) -> 2 | X12: =IF($L12=0,"",$H12-$I12) -> -2
A13: 11 | B13: 46040 | C13: BRIGHT | D13: YEMOLEE | E13: 2 | F13: 2 | G13: Played | H13: =IF($G13="Walkover_Home",Settings!$B$10,IF($G13="Walkover_Away",Settings!$B$11,IF($G13="Cancelled","",IF($E13="","",$E13)))) -> 2 | I13: =IF($G13="Walkover_Home",Settings!$B$11,IF($G13="Walkover_Away",Settings!$B$10,IF($G13="Cancelled","",IF($F13="","",$F13)))) -> 2 | J13: =IF($L13=0,"",IF($G13="Walkover_Home",Settings!$B$7,IF($G13="Walkover_Away",Settings!$B$8,IF($H13>$I13,Settings!$B$3,IF($H13<$I13,Settings!$B$4,Settings!$B$5))))) -> 1 | K13: =IF($L13=0,"",IF($G13="Walkover_Home",Settings!$B$8,IF($G13="Walkover_Away",Settings!$B$7,IF($I13>$H13,Settings!$B$3,IF($I13<$H13,Settings!$B$4,Settings!$B$5))))) -> 1 | L13: =IF($G13="Cancelled",0,IF(OR($H13="", $I13=""),0,1)) -> 1 | M13: =IF($L13=0,"",IF($H13>$I13,1,0)) -> 0 | N13: =IF($L13=0,"",IF($H13=$I13,1,0)) -> 1 | O13: =IF($L13=0,"",IF($H13<$I13,1,0)) -> 0 | P13: =IF($L13=0,"",IF($I13>$H13,1,0)) -> 0 | Q13: =IF($L13=0,"",IF($I13=$H13,1,0)) -> 1 | R13: =IF($L13=0,"",IF($I13<$H13,1,0)) -> 0 | S13: =IF($L13=0,"",IF($H13>$I13,$C13,IF($H13<$I13,$D13,"Draw"))) -> Draw | U13: =IF($L13=0,"",$H13-$I13) -> 0 | V13: =IF($L13=0,"",$I13-$H13) -> 0 | W13: =IF($L13=0,"",$I13-$H13) -> 0 | X13: =IF($L13=0,"",$H13-$I13) -> 0
A14: 12 | B14: 46040 | C14: RHYMEZ | D14: TACTICAL | E14: 4 | F14: 3 | G14: Played | H14: =IF($G14="Walkover_Home",Settings!$B$10,IF($G14="Walkover_Away",Settings!$B$11,IF($G14="Cancelled","",IF($E14="","",$E14)))) -> 4 | I14: =IF($G14="Walkover_Home",Settings!$B$11,IF($G14="Walkover_Away",Settings!$B$10,IF($G14="Cancelled","",IF($F14="","",$F14)))) -> 3 | J14: =IF($L14=0,"",IF($G14="Walkover_Home",Settings!$B$7,IF($G14="Walkover_Away",Settings!$B$8,IF($H14>$I14,Settings!$B$3,IF($H14<$I14,Settings!$B$4,Settings!$B$5))))) -> 3 | K14: =IF($L14=0,"",IF($G14="Walkover_Home",Settings!$B$8,IF($G14="Walkover_Away",Settings!$B$7,IF($I14>$H14,Settings!$B$3,IF($I14<$H14,Settings!$B$4,Settings!$B$5))))) -> 0 | L14: =IF($G14="Cancelled",0,IF(OR($H14="", $I14=""),0,1)) -> 1 | M14: =IF($L14=0,"",IF($H14>$I14,1,0)) -> 1 | N14: =IF($L14=0,"",IF($H14=$I14,1,0)) -> 0 | O14: =IF($L14=0,"",IF($H14<$I14,1,0)) -> 0 | P14: =IF($L14=0,"",IF($I14>$H14,1,0)) -> 0 | Q14: =IF($L14=0,"",IF($I14=$H14,1,0)) -> 0 | R14: =IF($L14=0,"",IF($I14<$H14,1,0)) -> 1 | S14: =IF($L14=0,"",IF($H14>$I14,$C14,IF($H14<$I14,$D14,"Draw"))) -> RHYMEZ | U14: =IF($L14=0,"",$H14-$I14) -> 1 | V14: =IF($L14=0,"",$I14-$H14) -> -1 | W14: =IF($L14=0,"",$I14-$H14) -> -1 | X14: =IF($L14=0,"",$H14-$I14) -> 1
A15: 13 | B15: 46040 | C15: BALO K | D15: MR OGA | G15: Walkover_Home | H15: =IF($G15="Walkover_Home",Settings!$B$10,IF($G15="Walkover_Away",Settings!$B$11,IF($G15="Cancelled","",IF($E15="","",$E15)))) -> 3 | I15: =IF($G15="Walkover_Home",Settings!$B$11,IF($G15="Walkover_Away",Settings!$B$10,IF($G15="Cancelled","",IF($F15="","",$F15)))) -> 0 | J15: =IF($L15=0,"",IF($G15="Walkover_Home",Settings!$B$7,IF($G15="Walkover_Away",Settings!$B$8,IF($H15>$I15,Settings!$B$3,IF($H15<$I15,Settings!$B$4,Settings!$B$5))))) -> 3 | K15: =IF($L15=0,"",IF($G15="Walkover_Home",Settings!$B$8,IF($G15="Walkover_Away",Settings!$B$7,IF($I15>$H15,Settings!$B$3,IF($I15<$H15,Settings!$B$4,Settings!$B$5))))) -> 0 | L15: =IF($G15="Cancelled",0,IF(OR($H15="", $I15=""),0,1)) -> 1 | M15: =IF($L15=0,"",IF($H15>$I15,1,0)) -> 1 | N15: =IF($L15=0,"",IF($H15=$I15,1,0)) -> 0 | O15: =IF($L15=0,"",IF($H15<$I15,1,0)) -> 0 | P15: =IF($L15=0,"",IF($I15>$H15,1,0)) -> 0 | Q15: =IF($L15=0,"",IF($I15=$H15,1,0)) -> 0 | R15: =IF($L15=0,"",IF($I15<$H15,1,0)) -> 1 | S15: =IF($L15=0,"",IF($H15>$I15,$C15,IF($H15<$I15,$D15,"Draw"))) -> BALO K | U15: =IF($L15=0,"",$H15-$I15) -> 3 | V15: =IF($L15=0,"",$I15-$H15) -> -3 | W15: =IF($L15=0,"",$I15-$H15) -> -3 | X15: =IF($L15=0,"",$H15-$I15) -> 3
A16: 14 | B16: 46040 | C16: DADABOI | D16: KINGNONEX | E16: 0 | F16: 10 | G16: Played | H16: =IF($G16="Walkover_Home",Settings!$B$10,IF($G16="Walkover_Away",Settings!$B$11,IF($G16="Cancelled","",IF($E16="","",$E16)))) -> 0 | I16: =IF($G16="Walkover_Home",Settings!$B$11,IF($G16="Walkover_Away",Settings!$B$10,IF($G16="Cancelled","",IF($F16="","",$F16)))) -> 10 | J16: =IF($L16=0,"",IF($G16="Walkover_Home",Settings!$B$7,IF($G16="Walkover_Away",Settings!$B$8,IF($H16>$I16,Settings!$B$3,IF($H16<$I16,Settings!$B$4,Settings!$B$5))))) -> 0 | K16: =IF($L16=0,"",IF($G16="Walkover_Home",Settings!$B$8,IF($G16="Walkover_Away",Settings!$B$7,IF($I16>$H16,Settings!$B$3,IF($I16<$H16,Settings!$B$4,Settings!$B$5))))) -> 3 | L16: =IF($G16="Cancelled",0,IF(OR($H16="", $I16=""),0,1)) -> 1 | M16: =IF($L16=0,"",IF($H16>$I16,1,0)) -> 0 | N16: =IF($L16=0,"",IF($H16=$I16,1,0)) -> 0 | O16: =IF($L16=0,"",IF($H16<$I16,1,0)) -> 1 | P16: =IF($L16=0,"",IF($I16>$H16,1,0)) -> 1 | Q16: =IF($L16=0,"",IF($I16=$H16,1,0)) -> 0 | R16: =IF($L16=0,"",IF($I16<$H16,1,0)) -> 0 | S16: =IF($L16=0,"",IF($H16>$I16,$C16,IF($H16<$I16,$D16,"Draw"))) -> KINGNONEX | U16: =IF($L16=0,"",$H16-$I16) -> -10 | V16: =IF($L16=0,"",$I16-$H16) -> 10 | W16: =IF($L16=0,"",$I16-$H16) -> 10 | X16: =IF($L16=0,"",$H16-$I16) -> -10
A17: 15 | B17: 46040 | C17: GURU | D17: ANIFE | E17: 6 | F17: 4 | G17: Played | H17: =IF($G17="Walkover_Home",Settings!$B$10,IF($G17="Walkover_Away",Settings!$B$11,IF($G17="Cancelled","",IF($E17="","",$E17)))) -> 6 | I17: =IF($G17="Walkover_Home",Settings!$B$11,IF($G17="Walkover_Away",Settings!$B$10,IF($G17="Cancelled","",IF($F17="","",$F17)))) -> 4 | J17: =IF($L17=0,"",IF($G17="Walkover_Home",Settings!$B$7,IF($G17="Walkover_Away",Settings!$B$8,IF($H17>$I17,Settings!$B$3,IF($H17<$I17,Settings!$B$4,Settings!$B$5))))) -> 3 | K17: =IF($L17=0,"",IF($G17="Walkover_Home",Settings!$B$8,IF($G17="Walkover_Away",Settings!$B$7,IF($I17>$H17,Settings!$B$3,IF($I17<$H17,Settings!$B$4,Settings!$B$5))))) -> 0 | L17: =IF($G17="Cancelled",0,IF(OR($H17="", $I17=""),0,1)) -> 1 | M17: =IF($L17=0,"",IF($H17>$I17,1,0)) -> 1 | N17: =IF($L17=0,"",IF($H17=$I17,1,0)) -> 0 | O17: =IF($L17=0,"",IF($H17<$I17,1,0)) -> 0 | P17: =IF($L17=0,"",IF($I17>$H17,1,0)) -> 0 | Q17: =IF($L17=0,"",IF($I17=$H17,1,0)) -> 0 | R17: =IF($L17=0,"",IF($I17<$H17,1,0)) -> 1 | S17: =IF($L17=0,"",IF($H17>$I17,$C17,IF($H17<$I17,$D17,"Draw"))) -> GURU | U17: =IF($L17=0,"",$H17-$I17) -> 2 | V17: =IF($L17=0,"",$I17-$H17) -> -2 | W17: =IF($L17=0,"",$I17-$H17) -> -2 | X17: =IF($L17=0,"",$H17-$I17) -> 2
A18: 16 | B18: 46040 | C18: WOLEVATION | D18: BLAISE99 | E18: 6 | F18: 4 | G18: Played | H18: =IF($G18="Walkover_Home",Settings!$B$10,IF($G18="Walkover_Away",Settings!$B$11,IF($G18="Cancelled","",IF($E18="","",$E18)))) -> 6 | I18: =IF($G18="Walkover_Home",Settings!$B$11,IF($G18="Walkover_Away",Settings!$B$10,IF($G18="Cancelled","",IF($F18="","",$F18)))) -> 4 | J18: =IF($L18=0,"",IF($G18="Walkover_Home",Settings!$B$7,IF($G18="Walkover_Away",Settings!$B$8,IF($H18>$I18,Settings!$B$3,IF($H18<$I18,Settings!$B$4,Settings!$B$5))))) -> 3 | K18: =IF($L18=0,"",IF($G18="Walkover_Home",Settings!$B$8,IF($G18="Walkover_Away",Settings!$B$7,IF($I18>$H18,Settings!$B$3,IF($I18<$H18,Settings!$B$4,Settings!$B$5))))) -> 0 | L18: =IF($G18="Cancelled",0,IF(OR($H18="", $I18=""),0,1)) -> 1 | M18: =IF($L18=0,"",IF($H18>$I18,1,0)) -> 1 | N18: =IF($L18=0,"",IF($H18=$I18,1,0)) -> 0 | O18: =IF($L18=0,"",IF($H18<$I18,1,0)) -> 0 | P18: =IF($L18=0,"",IF($I18>$H18,1,0)) -> 0 | Q18: =IF($L18=0,"",IF($I18=$H18,1,0)) -> 0 | R18: =IF($L18=0,"",IF($I18<$H18,1,0)) -> 1 | S18: =IF($L18=0,"",IF($H18>$I18,$C18,IF($H18<$I18,$D18,"Draw"))) -> WOLEVATION | U18: =IF($L18=0,"",$H18-$I18) -> 2 | V18: =IF($L18=0,"",$I18-$H18) -> -2 | W18: =IF($L18=0,"",$I18-$H18) -> -2 | X18: =IF($L18=0,"",$H18-$I18) -> 2
A19: 17 | B19: 46040 | C19: FLICK | D19: SON OF GOD | E19: 0 | F19: 6 | G19: Played | H19: =IF($G19="Walkover_Home",Settings!$B$10,IF($G19="Walkover_Away",Settings!$B$11,IF($G19="Cancelled","",IF($E19="","",$E19)))) -> 0 | I19: =IF($G19="Walkover_Home",Settings!$B$11,IF($G19="Walkover_Away",Settings!$B$10,IF($G19="Cancelled","",IF($F19="","",$F19)))) -> 6 | J19: =IF($L19=0,"",IF($G19="Walkover_Home",Settings!$B$7,IF($G19="Walkover_Away",Settings!$B$8,IF($H19>$I19,Settings!$B$3,IF($H19<$I19,Settings!$B$4,Settings!$B$5))))) -> 0 | K19: =IF($L19=0,"",IF($G19="Walkover_Home",Settings!$B$8,IF($G19="Walkover_Away",Settings!$B$7,IF($I19>$H19,Settings!$B$3,IF($I19<$H19,Settings!$B$4,Settings!$B$5))))) -> 3 | L19: =IF($G19="Cancelled",0,IF(OR($H19="", $I19=""),0,1)) -> 1 | M19: =IF($L19=0,"",IF($H19>$I19,1,0)) -> 0 | N19: =IF($L19=0,"",IF($H19=$I19,1,0)) -> 0 | O19: =IF($L19=0,"",IF($H19<$I19,1,0)) -> 1 | P19: =IF($L19=0,"",IF($I19>$H19,1,0)) -> 1 | Q19: =IF($L19=0,"",IF($I19=$H19,1,0)) -> 0 | R19: =IF($L19=0,"",IF($I19<$H19,1,0)) -> 0 | S19: =IF($L19=0,"",IF($H19>$I19,$C19,IF($H19<$I19,$D19,"Draw"))) -> SON OF GOD | U19: =IF($L19=0,"",$H19-$I19) -> -6 | V19: =IF($L19=0,"",$I19-$H19) -> 6 | W19: =IF($L19=0,"",$I19-$H19) -> 6 | X19: =IF($L19=0,"",$H19-$I19) -> -6
A20: 18 | B20: 46040 | C20: GAMEWITHJOSH | D20: BALO K | E20: 7 | F20: 5 | G20: Played | H20: =IF($G20="Walkover_Home",Settings!$B$10,IF($G20="Walkover_Away",Settings!$B$11,IF($G20="Cancelled","",IF($E20="","",$E20)))) -> 7 | I20: =IF($G20="Walkover_Home",Settings!$B$11,IF($G20="Walkover_Away",Settings!$B$10,IF($G20="Cancelled","",IF($F20="","",$F20)))) -> 5 | J20: =IF($L20=0,"",IF($G20="Walkover_Home",Settings!$B$7,IF($G20="Walkover_Away",Settings!$B$8,IF($H20>$I20,Settings!$B$3,IF($H20<$I20,Settings!$B$4,Settings!$B$5))))) -> 3 | K20: =IF($L20=0,"",IF($G20="Walkover_Home",Settings!$B$8,IF($G20="Walkover_Away",Settings!$B$7,IF($I20>$H20,Settings!$B$3,IF($I20<$H20,Settings!$B$4,Settings!$B$5))))) -> 0 | L20: =IF($G20="Cancelled",0,IF(OR($H20="", $I20=""),0,1)) -> 1 | M20: =IF($L20=0,"",IF($H20>$I20,1,0)) -> 1 | N20: =IF($L20=0,"",IF($H20=$I20,1,0)) -> 0 | O20: =IF($L20=0,"",IF($H20<$I20,1,0)) -> 0 | P20: =IF($L20=0,"",IF($I20>$H20,1,0)) -> 0 | Q20: =IF($L20=0,"",IF($I20=$H20,1,0)) -> 0 | R20: =IF($L20=0,"",IF($I20<$H20,1,0)) -> 1 | S20: =IF($L20=0,"",IF($H20>$I20,$C20,IF($H20<$I20,$D20,"Draw"))) -> GAMEWITHJOSH | U20: =IF($L20=0,"",$H20-$I20) -> 2 | V20: =IF($L20=0,"",$I20-$H20) -> -2 | W20: =IF($L20=0,"",$I20-$H20) -> -2 | X20: =IF($L20=0,"",$H20-$I20) -> 2
A21: 19 | B21: 46040 | C21: YEMOLEE | D21: BAJI SNR | E21: 6 | F21: 1 | G21: Played | H21: =IF($G21="Walkover_Home",Settings!$B$10,IF($G21="Walkover_Away",Settings!$B$11,IF($G21="Cancelled","",IF($E21="","",$E21)))) -> 6 | I21: =IF($G21="Walkover_Home",Settings!$B$11,IF($G21="Walkover_Away",Settings!$B$10,IF($G21="Cancelled","",IF($F21="","",$F21)))) -> 1 | J21: =IF($L21=0,"",IF($G21="Walkover_Home",Settings!$B$7,IF($G21="Walkover_Away",Settings!$B$8,IF($H21>$I21,Settings!$B$3,IF($H21<$I21,Settings!$B$4,Settings!$B$5))))) -> 3 | K21: =IF($L21=0,"",IF($G21="Walkover_Home",Settings!$B$8,IF($G21="Walkover_Away",Settings!$B$7,IF($I21>$H21,Settings!$B$3,IF($I21<$H21,Settings!$B$4,Settings!$B$5))))) -> 0 | L21: =IF($G21="Cancelled",0,IF(OR($H21="", $I21=""),0,1)) -> 1 | M21: =IF($L21=0,"",IF($H21>$I21,1,0)) -> 1 | N21: =IF($L21=0,"",IF($H21=$I21,1,0)) -> 0 | O21: =IF($L21=0,"",IF($H21<$I21,1,0)) -> 0 | P21: =IF($L21=0,"",IF($I21>$H21,1,0)) -> 0 | Q21: =IF($L21=0,"",IF($I21=$H21,1,0)) -> 0 | R21: =IF($L21=0,"",IF($I21<$H21,1,0)) -> 1 | S21: =IF($L21=0,"",IF($H21>$I21,$C21,IF($H21<$I21,$D21,"Draw"))) -> YEMOLEE | U21: =IF($L21=0,"",$H21-$I21) -> 5 | V21: =IF($L21=0,"",$I21-$H21) -> -5 | W21: =IF($L21=0,"",$I21-$H21) -> -5 | X21: =IF($L21=0,"",$H21-$I21) -> 5
A22: 20 | B22: 46040 | C22: BRIGHT | D22: DRACARYS | E22: 4 | F22: 7 | G22: Played | H22: =IF($G22="Walkover_Home",Settings!$B$10,IF($G22="Walkover_Away",Settings!$B$11,IF($G22="Cancelled","",IF($E22="","",$E22)))) -> 4 | I22: =IF($G22="Walkover_Home",Settings!$B$11,IF($G22="Walkover_Away",Settings!$B$10,IF($G22="Cancelled","",IF($F22="","",$F22)))) -> 7 | J22: =IF($L22=0,"",IF($G22="Walkover_Home",Settings!$B$7,IF($G22="Walkover_Away",Settings!$B$8,IF($H22>$I22,Settings!$B$3,IF($H22<$I22,Settings!$B$4,Settings!$B$5))))) -> 0 | K22: =IF($L22=0,"",IF($G22="Walkover_Home",Settings!$B$8,IF($G22="Walkover_Away",Settings!$B$7,IF($I22>$H22,Settings!$B$3,IF($I22<$H22,Settings!$B$4,Settings!$B$5))))) -> 3 | L22: =IF($G22="Cancelled",0,IF(OR($H22="", $I22=""),0,1)) -> 1 | M22: =IF($L22=0,"",IF($H22>$I22,1,0)) -> 0 | N22: =IF($L22=0,"",IF($H22=$I22,1,0)) -> 0 | O22: =IF($L22=0,"",IF($H22<$I22,1,0)) -> 1 | P22: =IF($L22=0,"",IF($I22>$H22,1,0)) -> 1 | Q22: =IF($L22=0,"",IF($I22=$H22,1,0)) -> 0 | R22: =IF($L22=0,"",IF($I22<$H22,1,0)) -> 0 | S22: =IF($L22=0,"",IF($H22>$I22,$C22,IF($H22<$I22,$D22,"Draw"))) -> DRACARYS | U22: =IF($L22=0,"",$H22-$I22) -> -3 | V22: =IF($L22=0,"",$I22-$H22) -> 3 | W22: =IF($L22=0,"",$I22-$H22) -> 3 | X22: =IF($L22=0,"",$H22-$I22) -> -3
A23: 21 | B23: 46040 | C23: TACTICAL | D23: WOLEVATION | E23: 3 | F23: 7 | G23: Played | H23: =IF($G23="Walkover_Home",Settings!$B$10,IF($G23="Walkover_Away",Settings!$B$11,IF($G23="Cancelled","",IF($E23="","",$E23)))) -> 3 | I23: =IF($G23="Walkover_Home",Settings!$B$11,IF($G23="Walkover_Away",Settings!$B$10,IF($G23="Cancelled","",IF($F23="","",$F23)))) -> 7 | J23: =IF($L23=0,"",IF($G23="Walkover_Home",Settings!$B$7,IF($G23="Walkover_Away",Settings!$B$8,IF($H23>$I23,Settings!$B$3,IF($H23<$I23,Settings!$B$4,Settings!$B$5))))) -> 0 | K23: =IF($L23=0,"",IF($G23="Walkover_Home",Settings!$B$8,IF($G23="Walkover_Away",Settings!$B$7,IF($I23>$H23,Settings!$B$3,IF($I23<$H23,Settings!$B$4,Settings!$B$5))))) -> 3 | L23: =IF($G23="Cancelled",0,IF(OR($H23="", $I23=""),0,1)) -> 1 | M23: =IF($L23=0,"",IF($H23>$I23,1,0)) -> 0 | N23: =IF($L23=0,"",IF($H23=$I23,1,0)) -> 0 | O23: =IF($L23=0,"",IF($H23<$I23,1,0)) -> 1 | P23: =IF($L23=0,"",IF($I23>$H23,1,0)) -> 1 | Q23: =IF($L23=0,"",IF($I23=$H23,1,0)) -> 0 | R23: =IF($L23=0,"",IF($I23<$H23,1,0)) -> 0 | S23: =IF($L23=0,"",IF($H23>$I23,$C23,IF($H23<$I23,$D23,"Draw"))) -> WOLEVATION | U23: =IF($L23=0,"",$H23-$I23) -> -4 | V23: =IF($L23=0,"",$I23-$H23) -> 4 | W23: =IF($L23=0,"",$I23-$H23) -> 4 | X23: =IF($L23=0,"",$H23-$I23) -> -4
A24: 22 | B24: 46040 | C24: SIMPLYY UZO | D24: KINGNONEX | E24: 1 | F24: 6 | G24: Played | H24: =IF($G24="Walkover_Home",Settings!$B$10,IF($G24="Walkover_Away",Settings!$B$11,IF($G24="Cancelled","",IF($E24="","",$E24)))) -> 1 | I24: =IF($G24="Walkover_Home",Settings!$B$11,IF($G24="Walkover_Away",Settings!$B$10,IF($G24="Cancelled","",IF($F24="","",$F24)))) -> 6 | J24: =IF($L24=0,"",IF($G24="Walkover_Home",Settings!$B$7,IF($G24="Walkover_Away",Settings!$B$8,IF($H24>$I24,Settings!$B$3,IF($H24<$I24,Settings!$B$4,Settings!$B$5))))) -> 0 | K24: =IF($L24=0,"",IF($G24="Walkover_Home",Settings!$B$8,IF($G24="Walkover_Away",Settings!$B$7,IF($I24>$H24,Settings!$B$3,IF($I24<$H24,Settings!$B$4,Settings!$B$5))))) -> 3 | L24: =IF($G24="Cancelled",0,IF(OR($H24="", $I24=""),0,1)) -> 1 | M24: =IF($L24=0,"",IF($H24>$I24,1,0)) -> 0 | N24: =IF($L24=0,"",IF($H24=$I24,1,0)) -> 0 | O24: =IF($L24=0,"",IF($H24<$I24,1,0)) -> 1 | P24: =IF($L24=0,"",IF($I24>$H24,1,0)) -> 1 | Q24: =IF($L24=0,"",IF($I24=$H24,1,0)) -> 0 | R24: =IF($L24=0,"",IF($I24<$H24,1,0)) -> 0 | S24: =IF($L24=0,"",IF($H24>$I24,$C24,IF($H24<$I24,$D24,"Draw"))) -> KINGNONEX | U24: =IF($L24=0,"",$H24-$I24) -> -5 | V24: =IF($L24=0,"",$I24-$H24) -> 5 | W24: =IF($L24=0,"",$I24-$H24) -> 5 | X24: =IF($L24=0,"",$H24-$I24) -> -5
A25: 23 | B25: 46040 | C25: KAYKAY | D25: DRACARYS | E25: 5 | F25: 4 | G25: Played | H25: =IF($G25="Walkover_Home",Settings!$B$10,IF($G25="Walkover_Away",Settings!$B$11,IF($G25="Cancelled","",IF($E25="","",$E25)))) -> 5 | I25: =IF($G25="Walkover_Home",Settings!$B$11,IF($G25="Walkover_Away",Settings!$B$10,IF($G25="Cancelled","",IF($F25="","",$F25)))) -> 4 | J25: =IF($L25=0,"",IF($G25="Walkover_Home",Settings!$B$7,IF($G25="Walkover_Away",Settings!$B$8,IF($H25>$I25,Settings!$B$3,IF($H25<$I25,Settings!$B$4,Settings!$B$5))))) -> 3 | K25: =IF($L25=0,"",IF($G25="Walkover_Home",Settings!$B$8,IF($G25="Walkover_Away",Settings!$B$7,IF($I25>$H25,Settings!$B$3,IF($I25<$H25,Settings!$B$4,Settings!$B$5))))) -> 0 | L25: =IF($G25="Cancelled",0,IF(OR($H25="", $I25=""),0,1)) -> 1 | M25: =IF($L25=0,"",IF($H25>$I25,1,0)) -> 1 | N25: =IF($L25=0,"",IF($H25=$I25,1,0)) -> 0 | O25: =IF($L25=0,"",IF($H25<$I25,1,0)) -> 0 | P25: =IF($L25=0,"",IF($I25>$H25,1,0)) -> 0 | Q25: =IF($L25=0,"",IF($I25=$H25,1,0)) -> 0 | R25: =IF($L25=0,"",IF($I25<$H25,1,0)) -> 1 | S25: =IF($L25=0,"",IF($H25>$I25,$C25,IF($H25<$I25,$D25,"Draw"))) -> KAYKAY | U25: =IF($L25=0,"",$H25-$I25) -> 1 | V25: =IF($L25=0,"",$I25-$H25) -> -1 | W25: =IF($L25=0,"",$I25-$H25) -> -1 | X25: =IF($L25=0,"",$H25-$I25) -> 1
A26: 24 | B26: 46040 | C26: KHALEEDOY | D26: GURU | E26: 2 | F26: 5 | G26: Played | H26: =IF($G26="Walkover_Home",Settings!$B$10,IF($G26="Walkover_Away",Settings!$B$11,IF($G26="Cancelled","",IF($E26="","",$E26)))) -> 2 | I26: =IF($G26="Walkover_Home",Settings!$B$11,IF($G26="Walkover_Away",Settings!$B$10,IF($G26="Cancelled","",IF($F26="","",$F26)))) -> 5 | J26: =IF($L26=0,"",IF($G26="Walkover_Home",Settings!$B$7,IF($G26="Walkover_Away",Settings!$B$8,IF($H26>$I26,Settings!$B$3,IF($H26<$I26,Settings!$B$4,Settings!$B$5))))) -> 0 | K26: =IF($L26=0,"",IF($G26="Walkover_Home",Settings!$B$8,IF($G26="Walkover_Away",Settings!$B$7,IF($I26>$H26,Settings!$B$3,IF($I26<$H26,Settings!$B$4,Settings!$B$5))))) -> 3 | L26: =IF($G26="Cancelled",0,IF(OR($H26="", $I26=""),0,1)) -> 1 | M26: =IF($L26=0,"",IF($H26>$I26,1,0)) -> 0 | N26: =IF($L26=0,"",IF($H26=$I26,1,0)) -> 0 | O26: =IF($L26=0,"",IF($H26<$I26,1,0)) -> 1 | P26: =IF($L26=0,"",IF($I26>$H26,1,0)) -> 1 | Q26: =IF($L26=0,"",IF($I26=$H26,1,0)) -> 0 | R26: =IF($L26=0,"",IF($I26<$H26,1,0)) -> 0 | S26: =IF($L26=0,"",IF($H26>$I26,$C26,IF($H26<$I26,$D26,"Draw"))) -> GURU | U26: =IF($L26=0,"",$H26-$I26) -> -3 | V26: =IF($L26=0,"",$I26-$H26) -> 3 | W26: =IF($L26=0,"",$I26-$H26) -> 3 | X26: =IF($L26=0,"",$H26-$I26) -> -3
A27: 25 | B27: 46046 | C27: BAJI SNR | D27: ANIFE | E27: 3 | F27: 5 | G27: Played | H27: =IF($G27="Walkover_Home",Settings!$B$10,IF($G27="Walkover_Away",Settings!$B$11,IF($G27="Cancelled","",IF($E27="","",$E27)))) -> 3 | I27: =IF($G27="Walkover_Home",Settings!$B$11,IF($G27="Walkover_Away",Settings!$B$10,IF($G27="Cancelled","",IF($F27="","",$F27)))) -> 5 | J27: =IF($L27=0,"",IF($G27="Walkover_Home",Settings!$B$7,IF($G27="Walkover_Away",Settings!$B$8,IF($H27>$I27,Settings!$B$3,IF($H27<$I27,Settings!$B$4,Settings!$B$5))))) -> 0 | K27: =IF($L27=0,"",IF($G27="Walkover_Home",Settings!$B$8,IF($G27="Walkover_Away",Settings!$B$7,IF($I27>$H27,Settings!$B$3,IF($I27<$H27,Settings!$B$4,Settings!$B$5))))) -> 3 | L27: =IF($G27="Cancelled",0,IF(OR($H27="", $I27=""),0,1)) -> 1 | M27: =IF($L27=0,"",IF($H27>$I27,1,0)) -> 0 | N27: =IF($L27=0,"",IF($H27=$I27,1,0)) -> 0 | O27: =IF($L27=0,"",IF($H27<$I27,1,0)) -> 1 | P27: =IF($L27=0,"",IF($I27>$H27,1,0)) -> 1 | Q27: =IF($L27=0,"",IF($I27=$H27,1,0)) -> 0 | R27: =IF($L27=0,"",IF($I27<$H27,1,0)) -> 0 | S27: =IF($L27=0,"",IF($H27>$I27,$C27,IF($H27<$I27,$D27,"Draw"))) -> ANIFE | U27: =IF($L27=0,"",$H27-$I27) -> -2 | V27: =IF($L27=0,"",$I27-$H27) -> 2 | W27: =IF($L27=0,"",$I27-$H27) -> 2 | X27: =IF($L27=0,"",$H27-$I27) -> -2
... A39: 37 | B39: 46046 | C39: ANIFE | D39: BRIGHT | E39: 6 | F39: 3 | G39: Played | H39: =IF($G39="Walkover_Home",Settings!$B$10,IF($G39="Walkover_Away",Settings!$B$11,IF($G39="Cancelled","",IF($E39="","",$E39)))) -> 6 | I39: =IF($G39="Walkover_Home",Settings!$B$11,IF($G39="Walkover_Away",Settings!$B$10,IF($G39="Cancelled","",IF($F39="","",$F39)))) -> 3 | J39: =IF($L39=0,"",IF($G39="Walkover_Home",Settings!$B$7,IF($G39="Walkover_Away",Settings!$B$8,IF($H39>$I39,Settings!$B$3,IF($H39<$I39,Settings!$B$4,Settings!$B$5))))) -> 3 | K39: =IF($L39=0,"",IF($G39="Walkover_Home",Settings!$B$8,IF($G39="Walkover_Away",Settings!$B$7,IF($I39>$H39,Settings!$B$3,IF($I39<$H39,Settings!$B$4,Settings!$B$5))))) -> 0 | L39: =IF($G39="Cancelled",0,IF(OR($H39="", $I39=""),0,1)) -> 1 | M39: =IF($L39=0,"",IF($H39>$I39,1,0)) -> 1 | N39: =IF($L39=0,"",IF($H39=$I39,1,0)) -> 0 | O39: =IF($L39=0,"",IF($H39<$I39,1,0)) -> 0 | P39: =IF($L39=0,"",IF($I39>$H39,1,0)) -> 0 | Q39: =IF($L39=0,"",IF($I39=$H39,1,0)) -> 0 | R39: =IF($L39=0,"",IF($I39<$H39,1,0)) -> 1 | S39: =IF($L39=0,"",IF($H39>$I39,$C39,IF($H39<$I39,$D39,"Draw"))) -> ANIFE | U39: =IF($L39=0,"",$H39-$I39) -> 3 | V39: =IF($L39=0,"",$I39-$H39) -> -3 | W39: =IF($L39=0,"",$I39-$H39) -> -3 | X39: =IF($L39=0,"",$H39-$I39) -> 3
A40: 38 | B40: 46046 | C40: SIMPLYY UZO | D40: KAYKAY | G40: Walkover_Away | H40: =IF($G40="Walkover_Home",Settings!$B$10,IF($G40="Walkover_Away",Settings!$B$11,IF($G40="Cancelled","",IF($E40="","",$E40)))) -> 0 | I40: =IF($G40="Walkover_Home",Settings!$B$11,IF($G40="Walkover_Away",Settings!$B$10,IF($G40="Cancelled","",IF($F40="","",$F40)))) -> 3 | J40: =IF($L40=0,"",IF($G40="Walkover_Home",Settings!$B$7,IF($G40="Walkover_Away",Settings!$B$8,IF($H40>$I40,Settings!$B$3,IF($H40<$I40,Settings!$B$4,Settings!$B$5))))) -> 0 | K40: =IF($L40=0,"",IF($G40="Walkover_Home",Settings!$B$8,IF($G40="Walkover_Away",Settings!$B$7,IF($I40>$H40,Settings!$B$3,IF($I40<$H40,Settings!$B$4,Settings!$B$5))))) -> 3 | L40: =IF($G40="Cancelled",0,IF(OR($H40="", $I40=""),0,1)) -> 1 | M40: =IF($L40=0,"",IF($H40>$I40,1,0)) -> 0 | N40: =IF($L40=0,"",IF($H40=$I40,1,0)) -> 0 | O40: =IF($L40=0,"",IF($H40<$I40,1,0)) -> 1 | P40: =IF($L40=0,"",IF($I40>$H40,1,0)) -> 1 | Q40: =IF($L40=0,"",IF($I40=$H40,1,0)) -> 0 | R40: =IF($L40=0,"",IF($I40<$H40,1,0)) -> 0 | S40: =IF($L40=0,"",IF($H40>$I40,$C40,IF($H40<$I40,$D40,"Draw"))) -> KAYKAY | U40: =IF($L40=0,"",$H40-$I40) -> -3 | V40: =IF($L40=0,"",$I40-$H40) -> 3 | W40: =IF($L40=0,"",$I40-$H40) -> 3 | X40: =IF($L40=0,"",$H40-$I40) -> -3
A41: 39 | B41: 46046 | C41: KHALEEDOY | D41: SON OF GOD | E41: 6 | F41: 6 | G41: Played | H41: =IF($G41="Walkover_Home",Settings!$B$10,IF($G41="Walkover_Away",Settings!$B$11,IF($G41="Cancelled","",IF($E41="","",$E41)))) -> 6 | I41: =IF($G41="Walkover_Home",Settings!$B$11,IF($G41="Walkover_Away",Settings!$B$10,IF($G41="Cancelled","",IF($F41="","",$F41)))) -> 6 | J41: =IF($L41=0,"",IF($G41="Walkover_Home",Settings!$B$7,IF($G41="Walkover_Away",Settings!$B$8,IF($H41>$I41,Settings!$B$3,IF($H41<$I41,Settings!$B$4,Settings!$B$5))))) -> 1 | K41: =IF($L41=0,"",IF($G41="Walkover_Home",Settings!$B$8,IF($G41="Walkover_Away",Settings!$B$7,IF($I41>$H41,Settings!$B$3,IF($I41<$H41,Settings!$B$4,Settings!$B$5))))) -> 1 | L41: =IF($G41="Cancelled",0,IF(OR($H41="", $I41=""),0,1)) -> 1 | M41: =IF($L41=0,"",IF($H41>$I41,1,0)) -> 0 | N41: =IF($L41=0,"",IF($H41=$I41,1,0)) -> 1 | O41: =IF($L41=0,"",IF($H41<$I41,1,0)) -> 0 | P41: =IF($L41=0,"",IF($I41>$H41,1,0)) -> 0 | Q41: =IF($L41=0,"",IF($I41=$H41,1,0)) -> 1 | R41: =IF($L41=0,"",IF($I41<$H41,1,0)) -> 0 | S41: =IF($L41=0,"",IF($H41>$I41,$C41,IF($H41<$I41,$D41,"Draw"))) -> Draw | U41: =IF($L41=0,"",$H41-$I41) -> 0 | V41: =IF($L41=0,"",$I41-$H41) -> 0 | W41: =IF($L41=0,"",$I41-$H41) -> 0 | X41: =IF($L41=0,"",$H41-$I41) -> 0
A42: 40 | B42: 46046 | C42: YEMOLEE | D42: FLICK | E42: 4 | F42: 4 | G42: Played | H42: =IF($G42="Walkover_Home",Settings!$B$10,IF($G42="Walkover_Away",Settings!$B$11,IF($G42="Cancelled","",IF($E42="","",$E42)))) -> 4 | I42: =IF($G42="Walkover_Home",Settings!$B$11,IF($G42="Walkover_Away",Settings!$B$10,IF($G42="Cancelled","",IF($F42="","",$F42)))) -> 4 | J42: =IF($L42=0,"",IF($G42="Walkover_Home",Settings!$B$7,IF($G42="Walkover_Away",Settings!$B$8,IF($H42>$I42,Settings!$B$3,IF($H42<$I42,Settings!$B$4,Settings!$B$5))))) -> 1 | K42: =IF($L42=0,"",IF($G42="Walkover_Home",Settings!$B$8,IF($G42="Walkover_Away",Settings!$B$7,IF($I42>$H42,Settings!$B$3,IF($I42<$H42,Settings!$B$4,Settings!$B$5))))) -> 1 | L42: =IF($G42="Cancelled",0,IF(OR($H42="", $I42=""),0,1)) -> 1 | M42: =IF($L42=0,"",IF($H42>$I42,1,0)) -> 0 | N42: =IF($L42=0,"",IF($H42=$I42,1,0)) -> 1 | O42: =IF($L42=0,"",IF($H42<$I42,1,0)) -> 0 | P42: =IF($L42=0,"",IF($I42>$H42,1,0)) -> 0 | Q42: =IF($L42=0,"",IF($I42=$H42,1,0)) -> 1 | R42: =IF($L42=0,"",IF($I42<$H42,1,0)) -> 0 | S42: =IF($L42=0,"",IF($H42>$I42,$C42,IF($H42<$I42,$D42,"Draw"))) -> Draw | U42: =IF($L42=0,"",$H42-$I42) -> 0 | V42: =IF($L42=0,"",$I42-$H42) -> 0 | W42: =IF($L42=0,"",$I42-$H42) -> 0 | X42: =IF($L42=0,"",$H42-$I42) -> 0
A43: 41 | B43: 46047 | C43: RHYMEZ | D43: GAMEWITHJOSH | E43: 3 | F43: 5 | G43: Played | H43: =IF($G43="Walkover_Home",Settings!$B$10,IF($G43="Walkover_Away",Settings!$B$11,IF($G43="Cancelled","",IF($E43="","",$E43)))) -> 3 | I43: =IF($G43="Walkover_Home",Settings!$B$11,IF($G43="Walkover_Away",Settings!$B$10,IF($G43="Cancelled","",IF($F43="","",$F43)))) -> 5 | J43: =IF($L43=0,"",IF($G43="Walkover_Home",Settings!$B$7,IF($G43="Walkover_Away",Settings!$B$8,IF($H43>$I43,Settings!$B$3,IF($H43<$I43,Settings!$B$4,Settings!$B$5))))) -> 0 | K43: =IF($L43=0,"",IF($G43="Walkover_Home",Settings!$B$8,IF($G43="Walkover_Away",Settings!$B$7,IF($I43>$H43,Settings!$B$3,IF($I43<$H43,Settings!$B$4,Settings!$B$5))))) -> 3 | L43: =IF($G43="Cancelled",0,IF(OR($H43="", $I43=""),0,1)) -> 1 | M43: =IF($L43=0,"",IF($H43>$I43,1,0)) -> 0 | N43: =IF($L43=0,"",IF($H43=$I43,1,0)) -> 0 | O43: =IF($L43=0,"",IF($H43<$I43,1,0)) -> 1 | P43: =IF($L43=0,"",IF($I43>$H43,1,0)) -> 1 | Q43: =IF($L43=0,"",IF($I43=$H43,1,0)) -> 0 | R43: =IF($L43=0,"",IF($I43<$H43,1,0)) -> 0 | S43: =IF($L43=0,"",IF($H43>$I43,$C43,IF($H43<$I43,$D43,"Draw"))) -> GAMEWITHJOSH | U43: =IF($L43=0,"",$H43-$I43) -> -2 | V43: =IF($L43=0,"",$I43-$H43) -> 2 | W43: =IF($L43=0,"",$I43-$H43) -> 2 | X43: =IF($L43=0,"",$H43-$I43) -> -2
A44: 42 | B44: 46047 | C44: SIMPLYY UZO | D44: MR OGA | E44: 3 | F44: 6 | G44: Played | H44: =IF($G44="Walkover_Home",Settings!$B$10,IF($G44="Walkover_Away",Settings!$B$11,IF($G44="Cancelled","",IF($E44="","",$E44)))) -> 3 | I44: =IF($G44="Walkover_Home",Settings!$B$11,IF($G44="Walkover_Away",Settings!$B$10,IF($G44="Cancelled","",IF($F44="","",$F44)))) -> 6 | J44: =IF($L44=0,"",IF($G44="Walkover_Home",Settings!$B$7,IF($G44="Walkover_Away",Settings!$B$8,IF($H44>$I44,Settings!$B$3,IF($H44<$I44,Settings!$B$4,Settings!$B$5))))) -> 0 | K44: =IF($L44=0,"",IF($G44="Walkover_Home",Settings!$B$8,IF($G44="Walkover_Away",Settings!$B$7,IF($I44>$H44,Settings!$B$3,IF($I44<$H44,Settings!$B$4,Settings!$B$5))))) -> 3 | L44: =IF($G44="Cancelled",0,IF(OR($H44="", $I44=""),0,1)) -> 1 | M44: =IF($L44=0,"",IF($H44>$I44,1,0)) -> 0 | N44: =IF($L44=0,"",IF($H44=$I44,1,0)) -> 0 | O44: =IF($L44=0,"",IF($H44<$I44,1,0)) -> 1 | P44: =IF($L44=0,"",IF($I44>$H44,1,0)) -> 1 | Q44: =IF($L44=0,"",IF($I44=$H44,1,0)) -> 0 | R44: =IF($L44=0,"",IF($I44<$H44,1,0)) -> 0 | S44: =IF($L44=0,"",IF($H44>$I44,$C44,IF($H44<$I44,$D44,"Draw"))) -> MR OGA | U44: =IF($L44=0,"",$H44-$I44) -> -3 | V44: =IF($L44=0,"",$I44-$H44) -> 3 | W44: =IF($L44=0,"",$I44-$H44) -> 3 | X44: =IF($L44=0,"",$H44-$I44) -> -3
A45: 43 | B45: 46047 | C45: YEMOLEE | D45: DADABOI | E45: 7 | F45: 3 | G45: Played | H45: =IF($G45="Walkover_Home",Settings!$B$10,IF($G45="Walkover_Away",Settings!$B$11,IF($G45="Cancelled","",IF($E45="","",$E45)))) -> 7 | I45: =IF($G45="Walkover_Home",Settings!$B$11,IF($G45="Walkover_Away",Settings!$B$10,IF($G45="Cancelled","",IF($F45="","",$F45)))) -> 3 | J45: =IF($L45=0,"",IF($G45="Walkover_Home",Settings!$B$7,IF($G45="Walkover_Away",Settings!$B$8,IF($H45>$I45,Settings!$B$3,IF($H45<$I45,Settings!$B$4,Settings!$B$5))))) -> 3 | K45: =IF($L45=0,"",IF($G45="Walkover_Home",Settings!$B$8,IF($G45="Walkover_Away",Settings!$B$7,IF($I45>$H45,Settings!$B$3,IF($I45<$H45,Settings!$B$4,Settings!$B$5))))) -> 0 | L45: =IF($G45="Cancelled",0,IF(OR($H45="", $I45=""),0,1)) -> 1 | M45: =IF($L45=0,"",IF($H45>$I45,1,0)) -> 1 | N45: =IF($L45=0,"",IF($H45=$I45,1,0)) -> 0 | O45: =IF($L45=0,"",IF($H45<$I45,1,0)) -> 0 | P45: =IF($L45=0,"",IF($I45>$H45,1,0)) -> 0 | Q45: =IF($L45=0,"",IF($I45=$H45,1,0)) -> 0 | R45: =IF($L45=0,"",IF($I45<$H45,1,0)) -> 1 | S45: =IF($L45=0,"",IF($H45>$I45,$C45,IF($H45<$I45,$D45,"Draw"))) -> YEMOLEE | U45: =IF($L45=0,"",$H45-$I45) -> 4 | V45: =IF($L45=0,"",$I45-$H45) -> -4 | W45: =IF($L45=0,"",$I45-$H45) -> -4 | X45: =IF($L45=0,"",$H45-$I45) -> 4
A46: 44 | B46: 46047 | C46: KAYKAY | D46: BRIGHT | E46: 6 | F46: 3 | G46: Played | H46: =IF($G46="Walkover_Home",Settings!$B$10,IF($G46="Walkover_Away",Settings!$B$11,IF($G46="Cancelled","",IF($E46="","",$E46)))) -> 6 | I46: =IF($G46="Walkover_Home",Settings!$B$11,IF($G46="Walkover_Away",Settings!$B$10,IF($G46="Cancelled","",IF($F46="","",$F46)))) -> 3 | J46: =IF($L46=0,"",IF($G46="Walkover_Home",Settings!$B$7,IF($G46="Walkover_Away",Settings!$B$8,IF($H46>$I46,Settings!$B$3,IF($H46<$I46,Settings!$B$4,Settings!$B$5))))) -> 3 | K46: =IF($L46=0,"",IF($G46="Walkover_Home",Settings!$B$8,IF($G46="Walkover_Away",Settings!$B$7,IF($I46>$H46,Settings!$B$3,IF($I46<$H46,Settings!$B$4,Settings!$B$5))))) -> 0 | L46: =IF($G46="Cancelled",0,IF(OR($H46="", $I46=""),0,1)) -> 1 | M46: =IF($L46=0,"",IF($H46>$I46,1,0)) -> 1 | N46: =IF($L46=0,"",IF($H46=$I46,1,0)) -> 0 | O46: =IF($L46=0,"",IF($H46<$I46,1,0)) -> 0 | P46: =IF($L46=0,"",IF($I46>$H46,1,0)) -> 0 | Q46: =IF($L46=0,"",IF($I46=$H46,1,0)) -> 0 | R46: =IF($L46=0,"",IF($I46<$H46,1,0)) -> 1 | S46: =IF($L46=0,"",IF($H46>$I46,$C46,IF($H46<$I46,$D46,"Draw"))) -> KAYKAY | U46: =IF($L46=0,"",$H46-$I46) -> 3 | V46: =IF($L46=0,"",$I46-$H46) -> -3 | W46: =IF($L46=0,"",$I46-$H46) -> -3 | X46: =IF($L46=0,"",$H46-$I46) -> 3
A47: 45 | B47: 46047 | C47: GAMEWITHJOSH | D47: SON OF GOD | E47: 4 | F47: 2 | G47: Played | H47: =IF($G47="Walkover_Home",Settings!$B$10,IF($G47="Walkover_Away",Settings!$B$11,IF($G47="Cancelled","",IF($E47="","",$E47)))) -> 4 | I47: =IF($G47="Walkover_Home",Settings!$B$11,IF($G47="Walkover_Away",Settings!$B$10,IF($G47="Cancelled","",IF($F47="","",$F47)))) -> 2 | J47: =IF($L47=0,"",IF($G47="Walkover_Home",Settings!$B$7,IF($G47="Walkover_Away",Settings!$B$8,IF($H47>$I47,Settings!$B$3,IF($H47<$I47,Settings!$B$4,Settings!$B$5))))) -> 3 | K47: =IF($L47=0,"",IF($G47="Walkover_Home",Settings!$B$8,IF($G47="Walkover_Away",Settings!$B$7,IF($I47>$H47,Settings!$B$3,IF($I47<$H47,Settings!$B$4,Settings!$B$5))))) -> 0 | L47: =IF($G47="Cancelled",0,IF(OR($H47="", $I47=""),0,1)) -> 1 | M47: =IF($L47=0,"",IF($H47>$I47,1,0)) -> 1 | N47: =IF($L47=0,"",IF($H47=$I47,1,0)) -> 0 | O47: =IF($L47=0,"",IF($H47<$I47,1,0)) -> 0 | P47: =IF($L47=0,"",IF($I47>$H47,1,0)) -> 0 | Q47: =IF($L47=0,"",IF($I47=$H47,1,0)) -> 0 | R47: =IF($L47=0,"",IF($I47<$H47,1,0)) -> 1 | S47: =IF($L47=0,"",IF($H47>$I47,$C47,IF($H47<$I47,$D47,"Draw"))) -> GAMEWITHJOSH | U47: =IF($L47=0,"",$H47-$I47) -> 2 | V47: =IF($L47=0,"",$I47-$H47) -> -2 | W47: =IF($L47=0,"",$I47-$H47) -> -2 | X47: =IF($L47=0,"",$H47-$I47) -> 2
A48: 46 | B48: 46047 | C48: RHYMEZ | D48: BRIGHT | E48: 5 | F48: 2 | G48: Played | H48: =IF($G48="Walkover_Home",Settings!$B$10,IF($G48="Walkover_Away",Settings!$B$11,IF($G48="Cancelled","",IF($E48="","",$E48)))) -> 5 | I48: =IF($G48="Walkover_Home",Settings!$B$11,IF($G48="Walkover_Away",Settings!$B$10,IF($G48="Cancelled","",IF($F48="","",$F48)))) -> 2 | J48: =IF($L48=0,"",IF($G48="Walkover_Home",Settings!$B$7,IF($G48="Walkover_Away",Settings!$B$8,IF($H48>$I48,Settings!$B$3,IF($H48<$I48,Settings!$B$4,Settings!$B$5))))) -> 3 | K48: =IF($L48=0,"",IF($G48="Walkover_Home",Settings!$B$8,IF($G48="Walkover_Away",Settings!$B$7,IF($I48>$H48,Settings!$B$3,IF($I48<$H48,Settings!$B$4,Settings!$B$5))))) -> 0 | L48: =IF($G48="Cancelled",0,IF(OR($H48="", $I48=""),0,1)) -> 1 | M48: =IF($L48=0,"",IF($H48>$I48,1,0)) -> 1 | N48: =IF($L48=0,"",IF($H48=$I48,1,0)) -> 0 | O48: =IF($L48=0,"",IF($H48<$I48,1,0)) -> 0 | P48: =IF($L48=0,"",IF($I48>$H48,1,0)) -> 0 | Q48: =IF($L48=0,"",IF($I48=$H48,1,0)) -> 0 | R48: =IF($L48=0,"",IF($I48<$H48,1,0)) -> 1 | S48: =IF($L48=0,"",IF($H48>$I48,$C48,IF($H48<$I48,$D48,"Draw"))) -> RHYMEZ | U48: =IF($L48=0,"",$H48-$I48) -> 3 | V48: =IF($L48=0,"",$I48-$H48) -> -3 | W48: =IF($L48=0,"",$I48-$H48) -> -3 | X48: =IF($L48=0,"",$H48-$I48) -> 3
A49: 47 | B49: 46047 | C49: GURU | D49: DRACARYS | E49: 6 | F49: 1 | G49: Played | H49: =IF($G49="Walkover_Home",Settings!$B$10,IF($G49="Walkover_Away",Settings!$B$11,IF($G49="Cancelled","",IF($E49="","",$E49)))) -> 6 | I49: =IF($G49="Walkover_Home",Settings!$B$11,IF($G49="Walkover_Away",Settings!$B$10,IF($G49="Cancelled","",IF($F49="","",$F49)))) -> 1 | J49: =IF($L49=0,"",IF($G49="Walkover_Home",Settings!$B$7,IF($G49="Walkover_Away",Settings!$B$8,IF($H49>$I49,Settings!$B$3,IF($H49<$I49,Settings!$B$4,Settings!$B$5))))) -> 3 | K49: =IF($L49=0,"",IF($G49="Walkover_Home",Settings!$B$8,IF($G49="Walkover_Away",Settings!$B$7,IF($I49>$H49,Settings!$B$3,IF($I49<$H49,Settings!$B$4,Settings!$B$5))))) -> 0 | L49: =IF($G49="Cancelled",0,IF(OR($H49="", $I49=""),0,1)) -> 1 | M49: =IF($L49=0,"",IF($H49>$I49,1,0)) -> 1 | N49: =IF($L49=0,"",IF($H49=$I49,1,0)) -> 0 | O49: =IF($L49=0,"",IF($H49<$I49,1,0)) -> 0 | P49: =IF($L49=0,"",IF($I49>$H49,1,0)) -> 0 | Q49: =IF($L49=0,"",IF($I49=$H49,1,0)) -> 0 | R49: =IF($L49=0,"",IF($I49<$H49,1,0)) -> 1 | S49: =IF($L49=0,"",IF($H49>$I49,$C49,IF($H49<$I49,$D49,"Draw"))) -> GURU | U49: =IF($L49=0,"",$H49-$I49) -> 5 | V49: =IF($L49=0,"",$I49-$H49) -> -5 | W49: =IF($L49=0,"",$I49-$H49) -> -5 | X49: =IF($L49=0,"",$H49-$I49) -> 5
A50: 48 | B50: 46047 | C50: BALO K | D50: SON OF GOD | E50: 3 | F50: 5 | G50: Played | H50: =IF($G50="Walkover_Home",Settings!$B$10,IF($G50="Walkover_Away",Settings!$B$11,IF($G50="Cancelled","",IF($E50="","",$E50)))) -> 3 | I50: =IF($G50="Walkover_Home",Settings!$B$11,IF($G50="Walkover_Away",Settings!$B$10,IF($G50="Cancelled","",IF($F50="","",$F50)))) -> 5 | J50: =IF($L50=0,"",IF($G50="Walkover_Home",Settings!$B$7,IF($G50="Walkover_Away",Settings!$B$8,IF($H50>$I50,Settings!$B$3,IF($H50<$I50,Settings!$B$4,Settings!$B$5))))) -> 0 | K50: =IF($L50=0,"",IF($G50="Walkover_Home",Settings!$B$8,IF($G50="Walkover_Away",Settings!$B$7,IF($I50>$H50,Settings!$B$3,IF($I50<$H50,Settings!$B$4,Settings!$B$5))))) -> 3 | L50: =IF($G50="Cancelled",0,IF(OR($H50="", $I50=""),0,1)) -> 1 | M50: =IF($L50=0,"",IF($H50>$I50,1,0)) -> 0 | N50: =IF($L50=0,"",IF($H50=$I50,1,0)) -> 0 | O50: =IF($L50=0,"",IF($H50<$I50,1,0)) -> 1 | P50: =IF($L50=0,"",IF($I50>$H50,1,0)) -> 1 | Q50: =IF($L50=0,"",IF($I50=$H50,1,0)) -> 0 | R50: =IF($L50=0,"",IF($I50<$H50,1,0)) -> 0 | S50: =IF($L50=0,"",IF($H50>$I50,$C50,IF($H50<$I50,$D50,"Draw"))) -> SON OF GOD | U50: =IF($L50=0,"",$H50-$I50) -> -2 | V50: =IF($L50=0,"",$I50-$H50) -> 2 | W50: =IF($L50=0,"",$I50-$H50) -> 2 | X50: =IF($L50=0,"",$H50-$I50) -> -2
A51: 49 | B51: 46047 | C51: BAJI SNR | D51: WOLEVATION | G51: Walkover_Away | H51: =IF($G51="Walkover_Home",Settings!$B$10,IF($G51="Walkover_Away",Settings!$B$11,IF($G51="Cancelled","",IF($E51="","",$E51)))) -> 0 | I51: =IF($G51="Walkover_Home",Settings!$B$11,IF($G51="Walkover_Away",Settings!$B$10,IF($G51="Cancelled","",IF($F51="","",$F51)))) -> 3 | J51: =IF($L51=0,"",IF($G51="Walkover_Home",Settings!$B$7,IF($G51="Walkover_Away",Settings!$B$8,IF($H51>$I51,Settings!$B$3,IF($H51<$I51,Settings!$B$4,Settings!$B$5))))) -> 0 | K51: =IF($L51=0,"",IF($G51="Walkover_Home",Settings!$B$8,IF($G51="Walkover_Away",Settings!$B$7,IF($I51>$H51,Settings!$B$3,IF($I51<$H51,Settings!$B$4,Settings!$B$5))))) -> 3 | L51: =IF($G51="Cancelled",0,IF(OR($H51="", $I51=""),0,1)) -> 1 | M51: =IF($L51=0,"",IF($H51>$I51,1,0)) -> 0 | N51: =IF($L51=0,"",IF($H51=$I51,1,0)) -> 0 | O51: =IF($L51=0,"",IF($H51<$I51,1,0)) -> 1 | P51: =IF($L51=0,"",IF($I51>$H51,1,0)) -> 1 | Q51: =IF($L51=0,"",IF($I51=$H51,1,0)) -> 0 | R51: =IF($L51=0,"",IF($I51<$H51,1,0)) -> 0 | S51: =IF($L51=0,"",IF($H51>$I51,$C51,IF($H51<$I51,$D51,"Draw"))) -> WOLEVATION | U51: =IF($L51=0,"",$H51-$I51) -> -3 | V51: =IF($L51=0,"",$I51-$H51) -> 3 | W51: =IF($L51=0,"",$I51-$H51) -> 3 | X51: =IF($L51=0,"",$H51-$I51) -> -3
...

Sheet Adjustments
A1: Point Adjustments / Deductions (enter negative numbers to deduct points)
A2: Date | B2: Player | C2: Metric | D2: Value | E2: Reason
B3: WOLEVATION | C3: GF | D3: -3 | E3: Stood up mid match and quit, decided to leave.

Sheet Stats
A1: Per-player Statistics (auto-calculated)
A2: Player | B2: P | C2: W | D2: D | E2: L | F2: GF | G2: GA | H2: GD | I2: PtsMatches | J2: PtsAdj | K2: TotalPts | L2: Pos | M2: Clean Sheets | N2: Avg GF | O2: Avg GA | P2: WinRate % | Q2: Biggest Win | R2: Biggest Loss | S2: Walkovers Given | T2: Walkovers Received | U2: Pts Per Game | V2: Last5Pts | W2: FormScore | X2: Adj_MP | Y2: Adj_W | Z2: Adj_D | AA2: Adj_L | AB2: Adj_GF | AC2: Adj_GA | AD2: Adj_GD | AE2: Adj_PTS
A3: =IF(Players!$B3="","",Players!$B3) -> MR OGA | B3: =IF($A3="","",(COUNTIFS(Matches!$C:$C,$A3,Matches!$L:$L,1)+COUNTIFS(Matches!$D:$D,$A3,Matches!$L:$L,1)) + $X3) -> 19 | C3: =IF($A3="","", COUNTIFS(Matches!$C:$C,$A3,Matches!$M:$M,TRUE)+COUNTIFS(Matches!$C:$C,$A3,Matches!$M:$M,1) +COUNTIFS(Matches!$D:$D,$A3,Matches!$P:$P,TRUE)+COUNTIFS(Matches!$D:$D,$A3,Matches!$P:$P,1) +$Y3) -> 10 | D3: =IF($A3="","", COUNTIFS(Matches!$C:$C,$A3,Matches!$N:$N,TRUE)+COUNTIFS(Matches!$C:$C,$A3,Matches!$N:$N,1) +COUNTIFS(Matches!$D:$D,$A3,Matches!$Q:$Q,TRUE)+COUNTIFS(Matches!$D:$D,$A3,Matches!$Q:$Q,1) +$Z3) -> 3 | E3: =IF($A3="","", COUNTIFS(Matches!$C:$C,$A3,Matches!$O:$O,TRUE)+COUNTIFS(Matches!$C:$C,$A3,Matches!$O:$O,1) +COUNTIFS(Matches!$D:$D,$A3,Matches!$R:$R,TRUE)+COUNTIFS(Matches!$D:$D,$A3,Matches!$R:$R,1) +$AA3) -> 6 | F3: =IF($A3="","",(SUMIFS(Matches!$H:$H,Matches!$C:$C,$A3)+SUMIFS(Matches!$I:$I,Matches!$D:$D,$A3)) + $AB3) -> 101 | G3: =IF($A3="","",(SUMIFS(Matches!$I:$I,Matches!$C:$C,$A3)+SUMIFS(Matches!$H:$H,Matches!$D:$D,$A3)) + $AC3) -> 87 | H3: =IF($A3="","",($F3-$G3) + $AD3) -> 14 | I3: =IF($A3="","", SUMIFS(Matches!$J:$J,Matches!$C:$C,$A3,Matches!$L:$L,TRUE)+SUMIFS(Matches!$J:$J,Matches!$C:$C,$A3,Matches!$L:$L,1) +SUMIFS(Matches!$K:$K,Matches!$D:$D,$A3,Matches!$L:$L,TRUE)+SUMIFS(Matches!$K:$K,Matches!$D:$D,$A3,Matches!$L:$L,1) ) -> 33 | J3: =IF($A3="","",$AE3) -> 0 | K3: =IF($A3="","", $I3 +($Y3*Settings!$B$3) +($Z3*Settings!$B$5) +($AA3*Settings!$B$6) +$AE3 ) -> 33 | L3: =IF($A3="","",1+COUNTIFS($K$3:$K$22,">"&$K3,$A$3:$A$22,"<>")+COUNTIFS($K$3:$K$22,$K3,$H$3:$H$22,">"&$H3,$A$3:$A$22,"<>")+COUNTIFS($K$3:$K$22,$K3,$H$3:$H$22,$H3,$F$3:$F$22,">"&$F3,$A$3:$A$22,"<>")+COUNTIFS($K$3:$K$22,$K3,$H$3:$H$22,$H3,$F$3:$F$22,$F3,$A$3:$A$22,"<"&$A3)) -> 6 | M3: =IF($A3="","",COUNTIFS(Matches!$C:$C,$A3,Matches!$I:$I,0,Matches!$L:$L,1)+COUNTIFS(Matches!$D:$D,$A3,Matches!$H:$H,0,Matches!$L:$L,1)) -> 1 | N3: =IF($A3="","",IF($B3=0,"",$F3/$B3)) -> 5.3157895 | O3: =IF($A3="","",IF($B3=0,"",$G3/$B3)) -> 4.5789474 | P3: =IF($A3="","",IF($B3=0,"",$C3/$B3)) -> 0.52631579 | Q3: =IF($A3="","",MAX(IFERROR(MAXIFS(Matches!$U:$U,Matches!$C:$C,$A3,Matches!$M:$M,1),0),IFERROR(MAXIFS(Matches!$V:$V,Matches!$D:$D,$A3,Matches!$P:$P,1),0))) -> 7 | R3: =IF($A3="","",MAX(IFERROR(MAXIFS(Matches!$W:$W,Matches!$C:$C,$A3,Matches!$O:$O,1),0),IFERROR(MAXIFS(Matches!$X:$X,Matches!$D:$D,$A3,Matches!$R:$R,1),0))) -> 4 | S3: =IF($A3="","",COUNTIFS(Matches!$G:$G,"Walkover_Home",Matches!$D:$D,$A3)+COUNTIFS(Matches!$G:$G,"Walkover_Away",Matches!$C:$C,$A3)) -> 1 | T3: =IF($A3="","",COUNTIFS(Matches!$G:$G,"Walkover_Home",Matches!$C:$C,$A3)+COUNTIFS(Matches!$G:$G,"Walkover_Away",Matches!$D:$D,$A3)) -> 1 | U3: =IF($A3="","",IF($B3=0,"",$K3/$B3)) -> 1.7368421 | V3: =IFERROR(__xludf.DUMMYFUNCTION("IF($A3="""","""",IFERROR( SUM( INDEX( QUERY( SORT(FILTER({Log!A:A,Log!G:G},Log!B:B=$A3),1,FALSE), ""select Col2 limit 5"", 0 ), ,1) ), 0))"),4.0) -> 4 | W3: =IF($A3="","",ROUND(100*V3/15,2)) -> 26.67 | X3: =IF($A3="","",IFERROR(SUMIFS(Adjustments!$D:$D,Adjustments!$B:$B,$A3,Adjustments!$C:$C,"MP"),0)) -> 0 | Y3: =IF($A3="","",IFERROR(SUMIFS(Adjustments!$D:$D,Adjustments!$B:$B,$A3,Adjustments!$C:$C,"W"),0)) -> 0 | Z3: =IF($A3="","",IFERROR(SUMIFS(Adjustments!$D:$D,Adjustments!$B:$B,$A3,Adjustments!$C:$C,"D"),0)) -> 0 | AA3: =IF($A3="","",IFERROR(SUMIFS(Adjustments!$D:$D,Adjustments!$B:$B,$A3,Adjustments!$C:$C,"L"),0)) -> 0 | AB3: =IF($A3="","",IFERROR(SUMIFS(Adjustments!$D:$D,Adjustments!$B:$B,$A3,Adjustments!$C:$C,"GF"),0)) -> 0 | AC3: =IF($A3="","",IFERROR(SUMIFS(Adjustments!$D:$D,Adjustments!$B:$B,$A3,Adjustments!$C:$C,"GA"),0)) -> 0 | AD3: =IF($A3="","",IFERROR(SUMIFS(Adjustments!$D:$D,Adjustments!$B:$B,$A3,Adjustments!$C:$C,"GD"),0)) -> 0 | AE3: =IF($A3="","",IFERROR(SUMIFS(Adjustments!$D:$D,Adjustments!$B:$B,$A3,Adjustments!$C:$C,"PTS"),0)) -> 0
A4: =IF(Players!$B4="","",Players!$B4) -> ANIFE | B4: =IF($A4="","",(COUNTIFS(Matches!$C:$C,$A4,Matches!$L:$L,1)+COUNTIFS(Matches!$D:$D,$A4,Matches!$L:$L,1)) + $X4) -> 19 | C4: =IF($A4="","", COUNTIFS(Matches!$C:$C,$A4,Matches!$M:$M,TRUE)+COUNTIFS(Matches!$C:$C,$A4,Matches!$M:$M,1) +COUNTIFS(Matches!$D:$D,$A4,Matches!$P:$P,TRUE)+COUNTIFS(Matches!$D:$D,$A4,Matches!$P:$P,1) +$Y4) -> 11 | D4: =IF($A4="","", COUNTIFS(Matches!$C:$C,$A4,Matches!$N:$N,TRUE)+COUNTIFS(Matches!$C:$C,$A4,Matches!$N:$N,1) +COUNTIFS(Matches!$D:$D,$A4,Matches!$Q:$Q,TRUE)+COUNTIFS(Matches!$D:$D,$A4,Matches!$Q:$Q,1) +$Z4) -> 3 | E4: =IF($A4="","", COUNTIFS(Matches!$C:$C,$A4,Matches!$O:$O,TRUE)+COUNTIFS(Matches!$C:$C,$A4,Matches!$O:$O,1) +COUNTIFS(Matches!$D:$D,$A4,Matches!$R:$R,TRUE)+COUNTIFS(Matches!$D:$D,$A4,Matches!$R:$R,1) +$AA4) -> 5 | F4: =IF($A4="","",(SUMIFS(Matches!$H:$H,Matches!$C:$C,$A4)+SUMIFS(Matches!$I:$I,Matches!$D:$D,$A4)) + $AB4) -> 117 | G4: =IF($A4="","",(SUMIFS(Matches!$I:$I,Matches!$C:$C,$A4)+SUMIFS(Matches!$H:$H,Matches!$D:$D,$A4)) + $AC4) -> 81 | H4: =IF($A4="","",($F4-$G4) + $AD4) -> 36 | I4: =IF($A4="","", SUMIFS(Matches!$J:$J,Matches!$C:$C,$A4,Matches!$L:$L,TRUE)+SUMIFS(Matches!$J:$J,Matches!$C:$C,$A4,Matches!$L:$L,1) +SUMIFS(Matches!$K:$K,Matches!$D:$D,$A4,Matches!$L:$L,TRUE)+SUMIFS(Matches!$K:$K,Matches!$D:$D,$A4,Matches!$L:$L,1) ) -> 36 | J4: =IF($A4="","",$AE4) -> 0 | K4: =IF($A4="","", $I4 +($Y4*Settings!$B$3) +($Z4*Settings!$B$5) +($AA4*Settings!$B$6) +$AE4 ) -> 36 | L4: =IF($A4="","",1+COUNTIFS($K$3:$K$22,">"&$K4,$A$3:$A$22,"<>")+COUNTIFS($K$3:$K$22,$K4,$H$3:$H$22,">"&$H4,$A$3:$A$22,"<>")+COUNTIFS($K$3:$K$22,$K4,$H$3:$H$22,$H4,$F$3:$F$22,">"&$F4,$A$3:$A$22,"<>")+COUNTIFS($K$3:$K$22,$K4,$H$3:$H$22,$H4,$F$3:$F$22,$F4,$A$3:$A$22,"<"&$A4)) -> 4 | M4: =IF($A4="","",COUNTIFS(Matches!$C:$C,$A4,Matches!$I:$I,0,Matches!$L:$L,1)+COUNTIFS(Matches!$D:$D,$A4,Matches!$H:$H,0,Matches!$L:$L,1)) -> 2 | N4: =IF($A4="","",IF($B4=0,"",$F4/$B4)) -> 6.1578947 | O4: =IF($A4="","",IF($B4=0,"",$G4/$B4)) -> 4.2631579 | P4: =IF($A4="","",IF($B4=0,"",$C4/$B4)) -> 0.57894737 | Q4: =IF($A4="","",MAX(IFERROR(MAXIFS(Matches!$U:$U,Matches!$C:$C,$A4,Matches!$M:$M,1),0),IFERROR(MAXIFS(Matches!$V:$V,Matches!$D:$D,$A4,Matches!$P:$P,1),0))) -> 14 | R4: =IF($A4="","",MAX(IFERROR(MAXIFS(Matches!$W:$W,Matches!$C:$C,$A4,Matches!$O:$O,1),0),IFERROR(MAXIFS(Matches!$X:$X,Matches!$D:$D,$A4,Matches!$R:$R,1),0))) -> 2 | S4: =IF($A4="","",COUNTIFS(Matches!$G:$G,"Walkover_Home",Matches!$D:$D,$A4)+COUNTIFS(Matches!$G:$G,"Walkover_Away",Matches!$C:$C,$A4)) -> 0 | T4: =IF($A4="","",COUNTIFS(Matches!$G:$G,"Walkover_Home",Matches!$C:$C,$A4)+COUNTIFS(Matches!$G:$G,"Walkover_Away",Matches!$D:$D,$A4)) -> 2 | U4: =IF($A4="","",IF($B4=0,"",$K4/$B4)) -> 1.8947368 | V4: =IFERROR(__xludf.DUMMYFUNCTION("IF($A4="""","""",IFERROR( SUM( INDEX( QUERY( SORT(FILTER({Log!A:A,Log!G:G},Log!B:B=$A4),1,FALSE), ""select Col2 limit 5"", 0 ), ,1) ), 0))"),11.0) -> 11 | W4: =IF($A4="","",ROUND(100*V4/15,2)) -> 73.33 | X4: =IF($A4="","",IFERROR(SUMIFS(Adjustments!$D:$D,Adjustments!$B:$B,$A4,Adjustments!$C:$C,"MP"),0)) -> 0 | Y4: =IF($A4="","",IFERROR(SUMIFS(Adjustments!$D:$D,Adjustments!$B:$B,$A4,Adjustments!$C:$C,"W"),0)) -> 0 | Z4: =IF($A4="","",IFERROR(SUMIFS(Adjustments!$D:$D,Adjustments!$B:$B,$A4,Adjustments!$C:$C,"D"),0)) -> 0 | AA4: =IF($A4="","",IFERROR(SUMIFS(Adjustments!$D:$D,Adjustments!$B:$B,$A4,Adjustments!$C:$C,"L"),0)) -> 0 | AB4: =IF($A4="","",IFERROR(SUMIFS(Adjustments!$D:$D,Adjustments!$B:$B,$A4,Adjustments!$C:$C,"GF"),0)) -> 0 | AC4: =IF($A4="","",IFERROR(SUMIFS(Adjustments!$D:$D,Adjustments!$B:$B,$A4,Adjustments!$C:$C,"GA"),0)) -> 0 | AD4: =IF($A4="","",IFERROR(SUMIFS(Adjustments!$D:$D,Adjustments!$B:$B,$A4,Adjustments!$C:$C,"GD"),0)) -> 0 | AE4: =IF($A4="","",IFERROR(SUMIFS(Adjustments!$D:$D,Adjustments!$B:$B,$A4,Adjustments!$C:$C,"PTS"),0)) -> 0
